<?xml version="1.0" encoding="utf-8"?>
<!-- This URDF was automatically created by SolidWorks to URDF Exporter! Originally created by Stephen Brawner (brawner@gmail.com) 
     Commit Version: 1.6.0-1-g15f4949  Build Version: 1.6.7594.29634
     For more information, please see http://wiki.ros.org/sw_urdf_exporter -->
<robot
  name="manipulator">
  <link
    name="base_link">
    <inertial>
      <origin
        xyz="0.4 0.4 0"
        rpy="0 0 0" />
      <mass
        value="580" />
      <inertia
        ixx="71.085"
        ixy="2.0309"
        ixz="-1.2338E-05"
        iyy="69.68"
        iyz="1.7321E-05"
        izz="58.927" />
    </inertial>
    <visual>
      <origin
        xyz="0 0 0"
        rpy="0 0 0" />
      <geometry>
        <mesh
          filename="package://manipulator/meshes/base_link.STL" />
      </geometry>
      <material
        name="">
        <color
          rgba="0.79216 0.81961 0.93333 1" />
      </material>
    </visual>
    <collision>
      <origin
        xyz="0 0 0"
        rpy="0 0 0" />
      <geometry>
        <mesh
          filename="package://manipulator/meshes/base_link.STL" />
      </geometry>
    </collision>
  </link>
  <link
    name="link1">
    <inertial>
      <origin
        xyz="0.5 0 0"
        rpy="0 0 0" />
      <mass
        value="7" />
      <inertia
        ixx="0.0089994"
        ixy="7.7329E-13"
        ixz="-9.353E-19"
        iyy="0.34018"
        iyz="-9.353E-19"
        izz="0.34001" />
    </inertial>
    <visual>
      <origin
        xyz="0 0 0"
        rpy="0 0 0" />
      <geometry>
        <mesh
          filename="package://manipulator/meshes/link1.STL" />
      </geometry>
      <material
        name="">
        <color
          rgba="0.79216 0.81961 0.93333 1" />
      </material>
    </visual>
    <collision>
      <origin
        xyz="0 0 0"
        rpy="0 0 0" />
      <geometry>
        <mesh
          filename="package://manipulator/meshes/link1.STL" />
      </geometry>
    </collision>
  </link>
  <joint
    name="joint1"
    type="continuous">
    <origin
      xyz="0.85 0.4 0"
      rpy="0 0 0.47901" />
    <parent
      link="base_link" />
    <child
      link="link1" />
    <axis
      xyz="0 0 -1" />
  </joint>
  <link
    name="link2">
    <inertial>
      <origin
        xyz="0.5 -9.4613E-13 2.7756E-17"
        rpy="0 0 0" />
      <mass
        value="7" />
      <inertia
        ixx="0.0089994"
        ixy="7.7329E-13"
        ixz="-9.353E-19"
        iyy="0.34018"
        iyz="-9.5138E-19"
        izz="0.34001" />
    </inertial>
    <visual>
      <origin
        xyz="0 0 0"
        rpy="0 0 0" />
      <geometry>
        <mesh
          filename="package://manipulator/meshes/link2.STL" />
      </geometry>
      <material
        name="">
        <color
          rgba="0.79216 0.81961 0.93333 1" />
      </material>
    </visual>
    <collision>
      <origin
        xyz="0 0 0"
        rpy="0 0 0" />
      <geometry>
        <mesh
          filename="package://manipulator/meshes/link2.STL" />
      </geometry>
    </collision>
  </link>
  <joint
    name="joint2"
    type="continuous">
    <origin
      xyz="0.9 0 0"
      rpy="0 0 -1.0833" />
    <parent
      link="link1" />
    <child
      link="link2" />
    <axis
      xyz="0 0 1" />
  </joint>
  <link
    name="link3">
    <inertial>
      <origin
        xyz="0.5 3.2951E-13 5.5511E-17"
        rpy="0 0 0" />
      <mass
        value="7" />
      <inertia
        ixx="0.0089994"
        ixy="-7.3522E-13"
        ixz="-7.3479E-18"
        iyy="0.34018"
        iyz="3.4735E-19"
        izz="0.34001" />
    </inertial>
    <visual>
      <origin
        xyz="0 0 0"
        rpy="0 0 0" />
      <geometry>
        <mesh
          filename="package://manipulator/meshes/link3.STL" />
      </geometry>
      <material
        name="">
        <color
          rgba="0.79216 0.81961 0.93333 1" />
      </material>
    </visual>
    <collision>
      <origin
        xyz="0 0 0"
        rpy="0 0 0" />
      <geometry>
        <mesh
          filename="package://manipulator/meshes/link3.STL" />
      </geometry>
    </collision>
  </link>
  <joint
    name="joint3"
    type="continuous">
    <origin
      xyz="0.9 0 0"
      rpy="0 0 0.93509" />
    <parent
      link="link2" />
    <child
      link="link3" />
    <axis
      xyz="0 0 -1" />
  </joint>
  <link
    name="end_effector">
    <inertial>
      <origin
        xyz="0.11786 8.0824E-14 -2.7756E-17"
        rpy="0 0 0" />
      <mass
        value="2.8" />
      <inertia
        ixx="0.039667"
        ixy="-3.9031E-18"
        ixz="7.1586E-19"
        iyy="0.011774"
        iyz="-1.2524E-17"
        izz="0.046774" />
    </inertial>
    <visual>
      <origin
        xyz="0 0 0"
        rpy="0 0 0" />
      <geometry>
        <mesh
          filename="package://manipulator/meshes/end_effector.STL" />
      </geometry>
      <material
        name="">
        <color
          rgba="1 1 1 1" />
      </material>
    </visual>
    <collision>
      <origin
        xyz="0 0 0"
        rpy="0 0 0" />
      <geometry>
        <mesh
          filename="package://manipulator/meshes/end_effector.STL" />
      </geometry>
    </collision>
  </link>
  <joint
    name="joint4"
    type="continuous">
    <origin
      xyz="0.9 0 0"
      rpy="0 0 -0.56721" />
    <parent
      link="link3" />
    <child
      link="end_effector" />
    <axis
      xyz="0 0 -1" />
  </joint>
</robot>