<mujoco model="manipulator">
  <!-- <compiler angle="radian"/> -->
  <statistic meansize="0.491504" extent="5.68645" center="0.732312 0.400546 1.00736e-07"/>
  <asset>
    <mesh name="base_link" file="base_link.STL"/>
    <mesh name="link1" file="link1.STL"/>
    <mesh name="link2" file="link2.STL"/>
    <mesh name="link3" file="link3.STL"/>
    <mesh name="end_effector" file="end_effector.STL"/>
    <!-- <texture name="grid" type="2d" builtin="checker" width="512" height="512" rgb1=".1 .2 .3" rgb2=".2 .3 .4"/>
    <material name="grid" texture="grid" texrepeat="1 1" texuniform="true" reflectance=".2"/> -->
  </asset>
  <option gravity="0 0 0" timestep="0.0001" integrator="implicitfast"/>
  <worldbody>
    <light mode="targetbody" diffuse=".5 .5 .5" pos="0 0 3" dir="0 0 -1"/>
    <!-- <geom type="plane" size="0 0 .05" material="grid"/> -->
    <body pos="0 0 0" euler="90 0 0">
      <inertial pos="0.4 0.4 0" mass="580" diaginertia="71.085 69.68 58.927"/>
      <joint type="free"/>
      <geom type="mesh" rgba="0.79216 0.81961 0.93333 1" mesh="base_link"/>
      <body name="link1" pos="0.85 0.4 0" quat="1 0 0 0">
        <inertial pos="0.5 0 0" quat="0.5 0.5 0.5 0.5" mass="20" diaginertia="0.34018 0.34001 0.0089994"/>
        <joint name="joint1" pos="0 0 0" axis="0 0 1" range="-90 90"/>
        <geom type="mesh" rgba="0.79216 0.81961 0.93333 1" mesh="link1"/>
        <body name="link2" pos="0.9 0 0" quat="1 0 0 0">
          <inertial pos="0.5 0 0" quat="0.5 0.5 0.5 0.5" mass="20" diaginertia="0.34018 0.34001 0.0089994"/>
          <joint name="joint2" pos="0 0 0" axis="0 0 1" range="-90 90"/>
          <geom type="mesh" rgba="0.79216 0.81961 0.93333 1" mesh="link2"/>
          <body name="link3" pos="0.9 0 0" quat="1 0 0 0">
            <inertial pos="0.5 0 0" quat="0.5 0.5 0.5 0.5" mass="20" diaginertia="0.34018 0.34001 0.0089994"/>
            <joint name="joint3" pos="0 0 0" axis="0 0 1" range="-90 90"/>
            <geom type="mesh" rgba="0.79216 0.81961 0.93333 1" mesh="link3"/>
            <body name="end_effector" pos="0.9 0 0" quat="1 0 0 0">
              <inertial pos="0.11786 0 0" quat="0.5 0.5 -0.5 0.5" mass="5" diaginertia="0.046774 0.039667 0.011774"/>
              <joint name="joint4" pos="0 0 0" axis="0 0 1" range="-90 90"/>
              <geom type="mesh" rgba="1 1 1 1" mesh="end_effector"/>
            </body>
          </body>
        </body>
      </body>
    </body>
  </worldbody>

  <actuator>
    <general name="actuator1" joint="joint1" dyntype="user" actdim="2" gainprm="0" biastype="user"/>
    <general name="actuator2" joint="joint2" dyntype="user" actdim="2" gainprm="0" biastype="user"/>
    <general name="actuator3" joint="joint3" dyntype="user" actdim="2" gainprm="0" biastype="user"/>
    <general name="actuator4" joint="joint4" dyntype="user" actdim="2" gainprm="0" biastype="user"/>
  </actuator>

  <!-- <actuator>
    <general name="actuator1" joint="joint1" />
    <general name="actuator2" joint="joint2" />
    <general name="actuator3" joint="joint3" />
    <general name="actuator4" joint="joint4" />
  </actuator> -->


</mujoco>
